Workbook

Sheet Revenue Model
A1: CONSTELLATION ENERGY (CEG) — REVENUE MODEL | $ in millions
A2: Source: SEC EDGAR 10-K/10-Q filings; Analyst consensus; Company press releases
B4: 2022A | C4: 2023A | D4: 2024A | E4: 2025A | F4: 2026E | G4: 2027E | H4: 2028E | I4: 2029E
A6: A. REVENUE BY BUSINESS SEGMENT ($M)
A8: Nuclear Generation (Wholesale + PPA) | B8: 16078 | C8: 15620 | D8: 15820 | E8: 17200 | F8: 22100 | G8: 23500 | H8: 24900 | I8: 26300
A9: Nuclear Generation Volume (GWh) | B9: 177300 | C9: 178500 | D9: 180900 | E9: 182690 | F9: 185000 | G9: 187000 | H9: 189000 | I9: 191000
A10: Avg. Realized Price incl. PTC ($/MWh) | B10: 90.7 | C10: 87.5 | D10: 87.4 | E10: 94.2 | F10: 119.5 | G10: 125.7 | H10: 131.7 | I10: 137.7
A11: Capacity Factor (%) | B11: 0.906 | C11: 0.912 | D11: 0.921 | E11: 0.923 | F11: 0.925 | G11: 0.927 | H11: 0.929 | I11: 0.93
A12: Natural Gas Generation (Calpine Fleet) | B12: 2350 | C12: 2280 | D12: 2100 | E12: 2050 | F12: 9800 | G12: 10400 | H12: 10900 | I12: 11300
A13: Calpine fleet capacity (GW) | B13: 0 | C13: 0 | D13: 0 | E13: 0 | F13: 26 | G13: 26 | H13: 26.5 | I13: 27
A14: Renewable Energy (Wind/Solar/Hydro/Geo) | B14: 850 | C14: 830 | D14: 810 | E14: 820 | F14: 900 | G14: 1000 | H14: 1100 | I14: 1200
A15: Retail Energy Supply (C&I + Residential) | B15: 3500 | C15: 3400 | D15: 3300 | E15: 3500 | F15: 3900 | G15: 4100 | H15: 4300 | I15: 4500
A16: Retail Customer Accounts (000s) | B16: 2600 | C16: 2550 | D16: 2500 | E16: 2500 | F16: 2700 | G16: 2750 | H16: 2800 | I16: 2850
A17: Energy Services & Government Contracts | B17: 1502 | C17: 1438 | D17: 1540 | E17: 1960 | F17: 2300 | G17: 2500 | H17: 2700 | I17: 2900
A18: Purchased Power Trading (net) | B18: 0 | C18: 0 | D18: 0 | E18: 0 | F18: -4600 | G18: -5000 | H18: -5400 | I18: -5700
A20: TOTAL REVENUE ($M) | B20: =SUM(B8,B12,B14,B15,B17,B18) | C20: =SUM(C8,C12,C14,C15,C17,C18) | D20: =SUM(D8,D12,D14,D15,D17,D18) | E20: =SUM(E8,E12,E14,E15,E17,E18) | F20: =SUM(F8,F12,F14,F15,F17,F18) | G20: =SUM(G8,G12,G14,G15,G17,G18) | H20: =SUM(H8,H12,H14,H15,H17,H18) | I20: =SUM(I8,I12,I14,I15,I17,I18)
A21: YoY Revenue Growth (%) | C21: =(C20-B20)/B20 | D21: =(D20-C20)/C20 | E21: =(E20-D20)/D20 | F21: =(F20-E20)/E20 | G21: =(G20-F20)/F20 | H21: =(H20-G20)/G20 | I21: =(I20-H20)/H20
A24: B. REVENUE BY GEOGRAPHY ($M)
A26: Mid-Atlantic | B26: 5800 | C26: 5138 | D26: 5200 | E26: 5400 | F26: 6800 | G26: 7200 | H26: 7600 | I26: 8000
A27: Midwest | B27: 5200 | C27: 4658 | D27: 4700 | E27: 4900 | F27: 5800 | G27: 6100 | H27: 6400 | I27: 6700
A28: New York | B28: 2100 | C28: 2021 | D28: 2050 | E28: 2100 | F28: 2400 | G28: 2500 | H28: 2600 | I28: 2700
A29: ERCOT (Texas) | B29: 1400 | C29: 1346 | D29: 1300 | E29: 1400 | F29: 4500 | G29: 4800 | H29: 5000 | I29: 5200
A30: California & West (Calpine) | B30: 0 | C30: 0 | D30: 0 | E30: 0 | F30: 5500 | G30: 5900 | H30: 6200 | I30: 6500
A31: Southeast & Other | B31: 9780 | C31: 10405 | D31: 10320 | E31: 11730 | F31: 9400 | G31: 10000 | H31: 10700 | I31: 11400
A33: TOTAL REVENUE ($M) | B33: =SUM(B26:B31) | C33: =SUM(C26:C31) | D33: =SUM(D26:D31) | E33: =SUM(E26:E31) | F33: =SUM(F26:F31) | G33: =SUM(G26:G31) | H33: =SUM(H26:H31) | I33: =SUM(I26:I31)
A35: C. KEY REVENUE ASSUMPTIONS
A37: Revenue CAGR 2025-2029 (implied) | I37: =(I20/E20)^(1/4)-1
A38: Nuclear % of Total Revenue | B38: =B8/B20 | C38: =C8/C20 | D38: =D8/D20 | E38: =E8/E20 | F38: =F8/F20 | G38: =G8/G20 | H38: =H8/H20 | I38: =I8/I20
A39: Long-term PPA contracted volume (GWh) | B39: 0 | C39: 0 | D39: 5000 | E39: 6000 | F39: 10500 | G39: 15000 | H39: 17000 | I39: 19000

Sheet Income Statement
A1: CONSTELLATION ENERGY (CEG) — INCOME STATEMENT | $ in millions
A2: GAAP basis; adjusted metrics noted separately | Source: SEC EDGAR 10-K/10-Q filings
B4: 2022A | C4: 2023A | D4: 2024A | E4: 2025A | F4: 2026E | G4: 2027E | H4: 2028E | I4: 2029E
A6: REVENUE
A7: Total Revenue | B7: 24280 | C7: 23568 | D7: 23570 | E7: 25530 | F7: 34400 | G7: 36500 | H7: 38500 | I7: 40500
A8: YoY Growth (%) | C8: =(C7-B7)/B7 | D8: =(D7-C7)/C7 | E8: =(E7-D7)/D7 | F8: =(F7-E7)/E7 | G8: =(G7-F7)/F7 | H8: =(H7-G7)/G7 | I8: =(I7-H7)/H7
A10: COST OF REVENUE
A11: Purchased Power & Fuel | B11: 16200 | C11: 13000 | D11: 12800 | E11: 14681 | F11: 19800 | G11: 20700 | H11: 21500 | I11: 22300
A12: % of Revenue | B12: =B11/B7 | C12: =C11/C7 | D12: =D11/D7 | E12: =E11/E7 | F12: =F11/F7 | G12: =G11/G7 | H12: =H11/H7 | I12: =I11/I7
A13: Operating & Maintenance (O&M) | B13: 5200 | C13: 4720 | D13: 5100 | E13: 6159 | F13: 7800 | G13: 8000 | H13: 8300 | I13: 8600
A14: % of Revenue | B14: =B13/B7 | C14: =C13/C7 | D14: =D13/D7 | E14: =E13/E7 | F14: =F13/F7 | G14: =G13/G7 | H14: =H13/H7 | I14: =I13/I7
A15: Depreciation & Amortization | B15: 840 | C15: 870 | D15: 950 | E15: 985 | F15: 1800 | G15: 1900 | H15: 1950 | I15: 2000
A16: Other Operating Costs / (Gains) | B16: 2240 | C16: 130 | D16: 522 | E16: 615 | F16: 400 | G16: 350 | H16: 300 | I16: 250
A17: Total Cost of Revenue | B17: =SUM(B11,B13,B15,B16) | C17: =SUM(C11,C13,C15,C16) | D17: =SUM(D11,D13,D15,D16) | E17: =SUM(E11,E13,E15,E16) | F17: =SUM(F11,F13,F15,F16) | G17: =SUM(G11,G13,G15,G16) | H17: =SUM(H11,H13,H15,H16) | I17: =SUM(I11,I13,I15,I16)
A19: GROSS PROFIT | B19: =B7-B17 | C19: =C7-C17 | D19: =D7-D17 | E19: =E7-E17 | F19: =F7-F17 | G19: =G7-G17 | H19: =H7-H17 | I19: =I7-I17
A20: Gross Margin (%) | B20: =B19/B7 | C20: =C19/C7 | D20: =D19/D7 | E20: =E19/E7 | F20: =F19/F7 | G20: =G19/G7 | H20: =H19/H7 | I20: =I19/I7
A22: EBITDA (Gross Profit + D&A) | B22: =B19+B15 | C22: =C19+C15 | D22: =D19+D15 | E22: =E19+E15 | F22: =F19+F15 | G22: =G19+G15 | H22: =H19+H15 | I22: =I19+I15
A23: EBITDA Margin (%) | B23: =B22/B7 | C23: =C22/C7 | D23: =D22/D7 | E23: =E22/E7 | F23: =F22/F7 | G23: =G22/G7 | H23: =H22/H7 | I23: =I22/I7
A25: EBIT / OPERATING INCOME | B25: =B19 | C25: =C19 | D25: =D19 | E25: =E19 | F25: =F19 | G25: =G19 | H25: =H19 | I25: =I19
A26: EBIT Margin (%) | B26: =B25/B7 | C26: =C25/C7 | D26: =D25/D7 | E26: =E25/E7 | F26: =F25/F7 | G26: =G25/G7 | H26: =H25/H7 | I26: =I25/I7
A28: BELOW THE LINE
A29: Interest Expense | B29: -600 | C29: -700 | D29: -750 | E29: -800 | F29: -1500 | G29: -1400 | H29: -1300 | I29: -1200
A30: Interest Income & Other | B30: 600 | C30: -2600 | D30: 500 | E30: 30 | F30: -100 | G30: -50 | H30: -50 | I30: -50
A32: PRE-TAX INCOME | B32: =SUM(B25,B29,B30) | C32: =SUM(C25,C29,C30) | D32: =SUM(D25,D29,D30) | E32: =SUM(E25,E29,E30) | F32: =SUM(F25,F29,F30) | G32: =SUM(G25,G29,G30) | H32: =SUM(H25,H29,H30) | I32: =SUM(I25,I29,I30)
A33: Income Tax Benefit / (Expense) | B33: 33 | C33: -167 | D33: -210 | E33: 0 | F33: -450 | G33: -615 | H33: -765 | I33: -915
A34: Effective Tax Rate (%) | C34: 0.108 | D34: 0.053 | E34: 0 | F34: 0.15 | G34: 0.15 | H34: 0.15 | I34: 0.15
A36: Non-controlling interest & other | B36: 0 | C36: 363 | D36: 0 | E36: 0 | F36: 0 | G36: 0 | H36: 0 | I36: 0
A38: NET INCOME (GAAP) | B38: -167 | C38: 1577 | D38: 3738 | E38: 2320 | F38: 3550 | G38: 4885 | H38: 6085 | I38: 7235
A39: Net Margin (GAAP %) | B39: =IF(B7=0,0,B38/B7) | C39: =IF(C7=0,0,C38/C7) | D39: =IF(D7=0,0,D38/D7) | E39: =IF(E7=0,0,E38/E7) | F39: =IF(F7=0,0,F38/F7) | G39: =IF(G7=0,0,G38/G7) | H39: =IF(H7=0,0,H38/H7) | I39: =IF(I7=0,0,I38/I7)
A41: PER SHARE DATA
A42: Diluted Shares Outstanding (M) | B42: 313 | C42: 314 | D42: 314 | E42: 313 | F42: 314 | G42: 312 | H42: 310 | I42: 308
A43: GAAP EPS (Diluted) | B43: =IF(B42=0,0,B38/B42) | C43: =IF(C42=0,0,C38/C42) | D43: =IF(D42=0,0,D38/D42) | E43: =IF(E42=0,0,E38/E42) | F43: =IF(F42=0,0,F38/F42) | G43: =IF(G42=0,0,G38/G42) | H43: =IF(H42=0,0,H38/H42) | I43: =IF(I42=0,0,I38/I42)
A44: Adjusted Operating EPS (non-GAAP) | B44: 3.4 | C44: 5 | D44: 8.67 | E44: 9.39 | F44: 11.74 | G44: 13.5 | H44: 15 | I44: 16.5
A45: YoY Adjusted EPS Growth (%) | C45: =(C44-B44)/B44 | D45: =(D44-C44)/C44 | E45: =(E44-D44)/D44 | F45: =(F44-E44)/E44 | G45: =(G44-F44)/F44 | H45: =(H44-G44)/G44 | I45: =(I44-H44)/H44
A46: Dividend Per Share | B46: 0 | C46: 0.84 | D46: 1.41 | E46: 1.68 | F46: 2 | G46: 2.4 | H46: 2.8 | I46: 3.2
A47: Dividend Payout Ratio (% Adj. EPS) | B47: =IF(B44=0,0,B46/B44) | C47: =IF(C44=0,0,C46/C44) | D47: =IF(D44=0,0,D46/D44) | E47: =IF(E44=0,0,E46/E44) | F47: =IF(F44=0,0,F46/F44) | G47: =IF(G44=0,0,G46/G44) | H47: =IF(H44=0,0,H46/H44) | I47: =IF(I44=0,0,I46/I44)
A49: ADJUSTED METRICS (NON-GAAP)
A50: Nuclear PTC Credit (45U, estimated) | B50: 0 | C50: 0 | D50: 1100 | E50: 1900 | F50: 2100 | G50: 2200 | H50: 2300 | I50: 2400
A51: Adjusted Net Income (non-GAAP, est.) | B51: 1067 | C51: 1570 | D51: 2723 | E51: 2948 | F51: 3685 | G51: 4212 | H51: 4650 | I51: 5082
A52: Adjusted EBITDA (est.) | B52: 2500 | C52: 3500 | D52: 5500 | E52: 6200 | F52: 8000 | G52: 9000 | H52: 9800 | I52: 10500
...

Sheet Cash Flow Statement
A1: CONSTELLATION ENERGY (CEG) — CASH FLOW STATEMENT | $ in millions
B4: 2022A | C4: 2023A | D4: 2024A | E4: 2025A | F4: 2026E | G4: 2027E | H4: 2028E | I4: 2029E
A6: OPERATING ACTIVITIES
A7: Net Income (GAAP) | B7: ='Income Statement'!B38 | C7: ='Income Statement'!C38 | D7: ='Income Statement'!D38 | E7: ='Income Statement'!E38 | F7: ='Income Statement'!F38 | G7: ='Income Statement'!G38 | H7: ='Income Statement'!H38 | I7: ='Income Statement'!I38
A8: Add: Depreciation & Amortization | B8: ='Income Statement'!B15 | C8: ='Income Statement'!C15 | D8: ='Income Statement'!D15 | E8: ='Income Statement'!E15 | F8: ='Income Statement'!F15 | G8: ='Income Statement'!G15 | H8: ='Income Statement'!H15 | I8: ='Income Statement'!I15
A9: Stock-Based Compensation | B9: 150 | C9: 170 | D9: 200 | E9: 220 | F9: 280 | G9: 290 | H9: 300 | I9: 310
A10: Deferred Income Taxes & Other | B10: 200 | C10: 1100 | D10: 100 | E10: 50 | F10: -100 | G10: 100 | H10: 100 | I10: 100
A11: Mark-to-Market / Non-cash items | B11: -600 | C11: 2600 | D11: -500 | E11: -30 | F11: 100 | G11: 50 | H11: 50 | I11: 50
A12: (Increase)/Decrease in Receivables | B12: -300 | C12: 500 | D12: -200 | E12: -100 | F12: -400 | G12: -200 | H12: -200 | I12: -200
A13: Increase/(Decrease) in Payables & Accruals | B13: 200 | C13: -300 | D13: 300 | E13: 100 | F13: 300 | G13: 100 | H13: 100 | I13: 100
A14: Other Working Capital Changes | B14: -100 | C14: 200 | D14: -100 | E14: -100 | F14: 0 | G14: 0 | H14: 0 | I14: 0
A16: CASH FROM OPERATIONS (CFO) | B16: =SUM(B7:B14) | C16: =SUM(C7:C14) | D16: =SUM(D7:D14) | E16: =SUM(E7:E14) | F16: =SUM(F7:F14) | G16: =SUM(G7:G14) | H16: =SUM(H7:H14) | I16: =SUM(I7:I14)
A17: CFO Margin (%) | B17: =IF('Income Statement'!B7=0,0,B16/'Income Statement'!B7) | C17: =IF('Income Statement'!C7=0,0,C16/'Income Statement'!C7) | D17: =IF('Income Statement'!D7=0,0,D16/'Income Statement'!D7) | E17: =IF('Income Statement'!E7=0,0,E16/'Income Statement'!E7) | F17: =IF('Income Statement'!F7=0,0,F16/'Income Statement'!F7) | G17: =IF('Income Statement'!G7=0,0,G16/'Income Statement'!G7) | H17: =IF('Income Statement'!H7=0,0,H16/'Income Statement'!H7) | I17: =IF('Income Statement'!I7=0,0,I16/'Income Statement'!I7)
A19: INVESTING ACTIVITIES
A20: Capital Expenditures (Maintenance + Growth) | B20: -1800 | C20: -2200 | D20: -2600 | E20: -2950 | F20: -3500 | G20: -3200 | H20: -3000 | I20: -2800
A21: CapEx as % of Revenue | B21: =ABS(B20)/'Income Statement'!B7 | C21: =ABS(C20)/'Income Statement'!C7 | D21: =ABS(D20)/'Income Statement'!D7 | E21: =ABS(E20)/'Income Statement'!E7 | F21: =ABS(F20)/'Income Statement'!F7 | G21: =ABS(G20)/'Income Statement'!G7 | H21: =ABS(H20)/'Income Statement'!H7 | I21: =ABS(I20)/'Income Statement'!I7
A22: Acquisitions (net of cash acquired) | B22: 0 | C22: 0 | D22: -600 | E22: -16400 | F22: 0 | G22: 0 | H22: 0 | I22: 0
A23: Nuclear Uprate Investments | B23: 0 | C23: 0 | D23: -200 | E23: -500 | F23: -800 | G23: -600 | H23: -400 | I23: -200
A24: Proceeds from Asset Sales & Other | B24: 0 | C24: 0 | D24: 300 | E24: 100 | F24: 200 | G24: 100 | H24: 100 | I24: 100
A26: CASH FROM INVESTING (CFI) | B26: =SUM(B20:B24) | C26: =SUM(C20:C24) | D26: =SUM(D20:D24) | E26: =SUM(E20:E24) | F26: =SUM(F20:F24) | G26: =SUM(G20:G24) | H26: =SUM(H20:H24) | I26: =SUM(I20:I24)
A28: FREE CASH FLOW (CFO + CapEx) | B28: =B16+B20 | C28: =C16+C20 | D28: =D16+D20 | E28: =E16+E20 | F28: =F16+F20 | G28: =G16+G20 | H28: =H16+H20 | I28: =I16+I20
A29: FCF Margin (%) | B29: =IF('Income Statement'!B7=0,0,B28/'Income Statement'!B7) | C29: =IF('Income Statement'!C7=0,0,C28/'Income Statement'!C7) | D29: =IF('Income Statement'!D7=0,0,D28/'Income Statement'!D7) | E29: =IF('Income Statement'!E7=0,0,E28/'Income Statement'!E7) | F29: =IF('Income Statement'!F7=0,0,F28/'Income Statement'!F7) | G29: =IF('Income Statement'!G7=0,0,G28/'Income Statement'!G7) | H29: =IF('Income Statement'!H7=0,0,H28/'Income Statement'!H7) | I29: =IF('Income Statement'!I7=0,0,I28/'Income Statement'!I7)
A30: FCF per Share ($) | B30: =IF('Income Statement'!B42=0,0,B28/'Income Statement'!B42) | C30: =IF('Income Statement'!C42=0,0,C28/'Income Statement'!C42) | D30: =IF('Income Statement'!D42=0,0,D28/'Income Statement'!D42) | E30: =IF('Income Statement'!E42=0,0,E28/'Income Statement'!E42) | F30: =IF('Income Statement'!F42=0,0,F28/'Income Statement'!F42) | G30: =IF('Income Statement'!G42=0,0,G28/'Income Statement'!G42) | H30: =IF('Income Statement'!H42=0,0,H28/'Income Statement'!H42) | I30: =IF('Income Statement'!I42=0,0,I28/'Income Statement'!I42)
A32: FINANCING ACTIVITIES
A33: Debt Issuance (net) | B33: 2000 | C33: 500 | D33: -500 | E33: 2000 | F33: 16000 | G33: -2000 | H33: -2000 | I33: -2000
A34: Share Repurchases | B34: 0 | C34: -400 | D34: -700 | E34: -500 | F34: -500 | G34: -500 | H34: -500 | I34: -500
A35: Dividends Paid | B35: 0 | C35: -263 | D35: -443 | E35: -527 | F35: -628 | G35: -748 | H35: -868 | I35: -988
A36: Other Financing Activities | B36: 200 | C36: -100 | D36: -200 | E36: -100 | F36: -100 | G36: 0 | H36: 0 | I36: 0
A38: CASH FROM FINANCING (CFF) | B38: =SUM(B33:B36) | C38: =SUM(C33:C36) | D38: =SUM(D33:D36) | E38: =SUM(E33:E36) | F38: =SUM(F33:F36) | G38: =SUM(G33:G36) | H38: =SUM(H33:H36) | I38: =SUM(I33:I36)
A40: NET CHANGE IN CASH | B40: =SUM(B16,B26,B38) | C40: =SUM(C16,C26,C38) | D40: =SUM(D16,D26,D38) | E40: =SUM(E16,E26,E38) | F40: =SUM(F16,F26,F38) | G40: =SUM(G16,G26,G38) | H40: =SUM(H16,H26,H38) | I40: =SUM(I16,I26,I38)
A41: Beginning Cash Balance | B41: 300 | C41: 200 | D41: 368 | E41: 311 | F41: 550 | G41: 1430 | H41: 2680 | I41: 4130
A42: Ending Cash Balance | B42: =B41+B40 | C42: =C41+C40 | D42: =D41+D40 | E42: =E41+E40 | F42: =F41+F40 | G42: =G41+G40 | H42: =H41+H40 | I42: =I41+I40

Sheet Balance Sheet
A1: CONSTELLATION ENERGY (CEG) — BALANCE SHEET | $ in millions
B4: 2022A | C4: 2023A | D4: 2024A | E4: 2025A | F4: 2026E | G4: 2027E | H4: 2028E | I4: 2029E
A6: ASSETS
A7: Current Assets
A8: Cash & Cash Equivalents | B8: 200 | C8: 368 | D8: 311 | E8: 550 | F8: 1430 | G8: 2680 | H8: 4130 | I8: 5680
A9: Accounts Receivable (net) | B9: 3200 | C9: 3000 | D9: 3100 | E9: 3200 | F9: 4200 | G9: 4400 | H9: 4600 | I9: 4800
A10: Fuel & Energy Inventories | B10: 600 | C10: 700 | D10: 750 | E10: 800 | F10: 1100 | G10: 1150 | H10: 1200 | I10: 1250
A11: Mark-to-Market Derivative Assets (current) | B11: 4000 | C11: 4200 | D11: 4500 | E11: 4800 | F11: 5200 | G11: 5000 | H11: 4800 | I11: 4600
A12: Prepaid & Other Current Assets | B12: 1500 | C12: 1600 | D12: 1700 | E12: 1800 | F12: 2500 | G12: 2600 | H12: 2700 | I12: 2800
A13: Total Current Assets | B13: =SUM(B8:B12) | C13: =SUM(C8:C12) | D13: =SUM(D8:D12) | E13: =SUM(E8:E12) | F13: =SUM(F8:F12) | G13: =SUM(G8:G12) | H13: =SUM(H8:H12) | I13: =SUM(I8:I12)
A15: Non-Current Assets
A16: Property, Plant & Equipment (Gross) | B16: 22000 | C16: 24000 | D16: 26000 | E16: 28000 | F16: 52000 | G16: 54000 | H16: 55500 | I16: 57000
A17: Less: Accumulated Depreciation | B17: -9000 | C17: -9800 | D17: -10700 | E17: -11600 | F17: -13400 | G17: -15300 | H17: -17250 | I17: -19250
A18: PP&E, Net | B18: =B16+B17 | C18: =C16+C17 | D18: =D16+D17 | E18: =E16+E17 | F18: =F16+F17 | G18: =G16+G17 | H18: =H16+H17 | I18: =I16+I17
A19: Goodwill | B19: 3500 | C19: 3800 | D19: 4000 | E19: 4100 | F19: 19000 | G19: 18800 | H19: 18600 | I19: 18400
A20: Intangible Assets (net) | B20: 1200 | C20: 1100 | D20: 1000 | E20: 900 | F20: 5500 | G20: 5000 | H20: 4500 | I20: 4000
A21: Nuclear Decommissioning Trust Funds | B21: 8000 | C21: 9000 | D21: 10000 | E21: 11000 | F21: 11500 | G21: 12000 | H21: 12500 | I21: 13000
A22: Mark-to-Market Derivative Assets (LT) | B22: 4200 | C22: 4500 | D22: 4700 | E22: 5000 | F22: 5500 | G22: 5200 | H22: 4900 | I22: 4600
A23: Other Non-Current Assets | B23: 2209 | C23: 2990 | D23: 3115 | E23: 3476 | F23: 4000 | G23: 4100 | H23: 4200 | I23: 4300
A24: Total Non-Current Assets | B24: =SUM(B18:B23) | C24: =SUM(C18:C23) | D24: =SUM(D18:D23) | E24: =SUM(E18:E23) | F24: =SUM(F18:F23) | G24: =SUM(G18:G23) | H24: =SUM(H18:H23) | I24: =SUM(I18:I23)
A26: TOTAL ASSETS | B26: =B13+B24 | C26: =C13+C24 | D26: =D13+D24 | E26: =E13+E24 | F26: =F13+F24 | G26: =G13+G24 | H26: =H13+H24 | I26: =I13+I24
A28: LIABILITIES & SHAREHOLDERS' EQUITY
A29: Current Liabilities
A30: Accounts Payable & Accrued Expenses | B30: 2000 | C30: 2200 | D30: 2400 | E30: 2500 | F30: 3500 | G30: 3600 | H30: 3700 | I30: 3800
A31: Mark-to-Market Derivative Liabilities (current) | B31: 4500 | C31: 4800 | D31: 5000 | E31: 5200 | F31: 5700 | G31: 5400 | H31: 5100 | I31: 4800
A32: Current Portion of Long-Term Debt | B32: 500 | C32: 600 | D32: 400 | E32: 500 | F32: 1500 | G32: 1500 | H32: 1500 | I32: 1500
A33: Other Current Liabilities | B33: 1500 | C33: 1600 | D33: 1700 | E33: 1800 | F33: 2500 | G33: 2600 | H33: 2700 | I33: 2800
A34: Total Current Liabilities | B34: =SUM(B30:B33) | C34: =SUM(C30:C33) | D34: =SUM(D30:D33) | E34: =SUM(E30:E33) | F34: =SUM(F30:F33) | G34: =SUM(G30:G33) | H34: =SUM(H30:H33) | I34: =SUM(I30:I33)
A36: Non-Current Liabilities
A37: Long-Term Debt (net of current portion) | B37: 6800 | C37: 8661 | D37: 8012 | E37: 7500 | F37: 23000 | G37: 21000 | H37: 19000 | I37: 17000
A38: Nuclear Asset Retirement Obligations | B38: 5000 | C38: 5500 | D38: 6000 | E38: 6500 | F38: 7000 | G38: 7200 | H38: 7400 | I38: 7600
A39: Mark-to-Market Derivative Liabilities (LT) | B39: 4200 | C39: 4500 | D39: 4700 | E39: 4900 | F39: 5400 | G39: 5100 | H39: 4800 | I39: 4500
A40: Deferred Income Taxes | B40: 3000 | C40: 3200 | D40: 3400 | E40: 3600 | F40: 5000 | G40: 5100 | H40: 5200 | I40: 5300
A41: Other Non-Current Liabilities | B41: 3600 | C41: 3800 | D41: 4000 | E41: 4100 | F41: 5500 | G41: 5600 | H41: 5700 | I41: 5800
A42: Total Non-Current Liabilities | B42: =SUM(B37:B41) | C42: =SUM(C37:C41) | D42: =SUM(D37:D41) | E42: =SUM(E37:E41) | F42: =SUM(F37:F41) | G42: =SUM(G37:G41) | H42: =SUM(H37:H41) | I42: =SUM(I37:I41)
A44: TOTAL LIABILITIES | B44: =B34+B42 | C44: =C34+C42 | D44: =D34+D42 | E44: =E34+E42 | F44: =F34+F42 | G44: =G34+G42 | H44: =H34+H42 | I44: =I34+I42
A46: Shareholders' Equity
A47: Common Stock & Additional Paid-In Capital | B47: 13500 | C47: 13700 | D47: 13900 | E47: 14000 | F47: 14200 | G47: 14400 | H47: 14600 | I47: 14800
A48: Retained Earnings / (Accumulated Deficit) | B48: -5000 | C48: -4500 | D48: -1200 | E48: 1500 | F48: 4050 | G48: 7685 | H48: 11470 | I48: 15455
A49: Accumulated Other Comprehensive Income / (Loss) | B49: -200 | C49: -300 | D49: -400 | E49: -500 | F49: -200 | G49: -200 | H49: -200 | I49: -200
...

Sheet Scenarios
A1: CONSTELLATION ENERGY (CEG) — SCENARIO ANALYSIS
A3: BULL / BASE / BEAR CASE ASSUMPTIONS (Projection Period 2026E–2029E)
A5: KEY REVENUE & PROFITABILITY ASSUMPTIONS | B5: BULL CASE | C5: BASE CASE | D5: BEAR CASE
A7: Revenue CAGR 2025→2029 | B7: 0.21 | C7: 0.17 | D7: 0.1
A8: Nuclear PPA contracted share (2029) | B8: 0.5 | C8: 0.4 | D8: 0.3
A9: Calpine EBITDA contribution ($M, 2026) | B9: 2500 | C9: 2000 | D9: 1500
A10: Adj. EBITDA Margin (2029) | B10: 0.3 | C10: 0.27 | D10: 0.22
A11: CapEx as % of Revenue (2029) | B11: 0.07 | C11: 0.08 | D11: 0.1
A12: Annual Debt Repayment ($M, avg) | B12: 2500 | C12: 2000 | D12: 1500
A13: Share Buyback ($M/yr avg) | B13: 700 | C13: 500 | D13: 300
A14: Nuclear capacity factor | B14: 0.93 | C14: 0.925 | D14: 0.9
A15: Realized nuclear price $/MWh (2029) | B15: 152 | C15: 138 | D15: 118
A17: 2026E FINANCIAL OUTPUTS
B18: BULL | C18: BASE | D18: BEAR
A19: Total Revenue ($M) | B19: 37500 | C19: 34400 | D19: 31000
A20: Adj. EBITDA ($M) | B20: 10200 | C20: 8000 | D20: 6800
A21: Adj. EBITDA Margin | B21: 0.272 | C21: 0.233 | D21: 0.219
A22: Adj. Net Income ($M) | B22: 4040 | C22: 3685 | D22: 3130
A23: Adj. EPS | B23: 12.8 | C23: 11.74 | D23: 9.9
A24: Free Cash Flow ($M) | B24: 3000 | C24: 2000 | D24: 1000
A25: Net Debt / EBITDA (x) | B25: 3.1x | C25: 3.8x | D25: 4.8x
A28: 2029E FINANCIAL OUTPUTS
B29: BULL | C29: BASE | D29: BEAR
A30: Total Revenue ($M) | B30: 48000 | C30: 40500 | D30: 33500
A31: Adj. EBITDA ($M) | B31: 14400 | C31: 10500 | D31: 7400
A32: Adj. EBITDA Margin | B32: 0.3 | C32: 0.259 | D32: 0.221
A33: Adj. Net Income ($M) | B33: 6500 | C33: 5082 | D33: 3700
A34: Adj. EPS | B34: 21 | C34: 16.5 | D34: 12
A35: Free Cash Flow ($M) | B35: 6000 | C35: 4000 | D35: 1500
A36: Cumulative FCF 2026-2029 ($M) | B36: 18000 | C36: 12000 | D36: 5500
A37: Net Debt / EBITDA (x) | B37: 0.9x | C37: 2.0x | D37: 3.8x
A38: Implied Stock Price (16x P/E) | B38: $336 | C38: $264 | D38: $192
A41: SCENARIO NARRATIVE
A43: BULL CASE
A44: All 5,650 MW of PPA pipeline executes by 2028; Calpine synergies of $500M+ achieved; nuclear uprates deliver ahead of schedule; hyperscaler demand accelerates, driving additional premium contracts; power prices elevated by AI-driven demand surge; no adverse regulatory/PTC changes. EPS CAGR ~28% (2025→2029).
A46: BASE CASE
A47: PPA pipeline executes per current schedule (Microsoft 2027, Meta ongoing); Calpine synergies ~$300M achieved by 2027; nuclear capacity factors hold ~92-93%; 45U PTC provides floor through 2027 before gradual phase-down; moderate power price appreciation; steady debt deleveraging. EPS CAGR ~15% (2025→2029).
A49: BEAR CASE
A50: Crane Clean Energy Center restart delayed to 2028+; Calpine integration costs exceed budget; adverse FERC market rule changes reduce capacity revenues; 45U PTC modified legislatively; wholesale power prices compress due to renewable overbuild; integration distraction slows new PPA origination. EPS CAGR ~6% (2025→2029).

Sheet DCF Inputs
A1: CONSTELLATION ENERGY (CEG) — DCF INPUTS | $ in millions
A2: Prepared for Task 3 Valuation Analysis | Base Case assumptions
B4: 2026E | C4: 2027E | D4: 2028E | E4: 2029E | G4: Notes / Source
A6: UNLEVERED FREE CASH FLOW BRIDGE
A8: EBIT (Operating Income, Adjusted) | B8: 4600 | C8: 5550 | D8: 6450 | E8: 7350 | G8: From Income Statement tab, adjusted for non-cash items
A9: Effective Tax Rate (on EBIT) | B9: 0.15 | C9: 0.15 | D9: 0.15 | E9: 0.15 | G9: Blended rate; 45U PTC reduces cash taxes materially
A10: NOPAT (Net Operating Profit After Tax) | B10: =B8*(1-B9) | C10: =C8*(1-C9) | D10: =D8*(1-D9) | E10: =E8*(1-E9)
A12: (+) Depreciation & Amortization | B12: 1800 | C12: 1900 | D12: 1950 | E12: 2000
A13: (-) Capital Expenditures | B13: -3500 | C13: -3200 | D13: -3000 | E13: -2800
A14: (-) Change in Net Working Capital | B14: -300 | C14: -200 | D14: -200 | E14: -200
A16: UNLEVERED FREE CASH FLOW (UFCF) | B16: =SUM(B10,B12,B13,B14) | C16: =SUM(C10,C12,C13,C14) | D16: =SUM(D10,D12,D13,D14) | E16: =SUM(E10,E12,E13,E14)
A17: UFCF Margin (%) | B17: =IF('Income Statement'!B7=0,0,B16/'Income Statement'!B7) | C17: =IF('Income Statement'!C7=0,0,C16/'Income Statement'!C7) | D17: =IF('Income Statement'!D7=0,0,D16/'Income Statement'!D7) | E17: =IF('Income Statement'!E7=0,0,E16/'Income Statement'!E7)
A18: YoY UFCF Growth (%) | C18: =IF(B16=0,0,(C16-B16)/B16) | D18: =IF(C16=0,0,(D16-C16)/C16) | E18: =IF(D16=0,0,(E16-D16)/D16)
A20: WACC ASSUMPTIONS
A22: Risk-Free Rate (10-yr UST yield) | B22: 0.044 | G22: US Treasury 10-year as of June 2026
A23: Equity Risk Premium | B23: 0.055 | G23: Damodaran market ERP estimate
A24: Beta (5-yr monthly vs S&P 500) | B24: 0.65 | G24: Constellation regulated-ish utility characteristics; source: Bloomberg
A25: Cost of Equity (CAPM) | B25: =B22+B24*B23 | G25: =Risk-Free Rate + Beta × ERP
A26: Pre-Tax Cost of Debt | B26: 0.055 | G26: Blended rate on post-Calpine debt stack
A27: Tax Rate (for after-tax cost) | B27: 0.15 | G27: Blended effective rate
A28: After-Tax Cost of Debt | B28: =B26*(1-B27) | G28: =Pre-Tax Cost × (1 - Tax Rate)
A29: Equity Weight (% of Total Capital) | B29: 0.45 | G29: Market cap / (Market cap + Net Debt)
A30: Debt Weight (% of Total Capital) | B30: 0.55 | G30: Net Debt / (Market cap + Net Debt)
A31: WACC | B31: =B29*B25+B30*B28 | G31: =E% × Cost of Equity + D% × After-Tax Cost of Debt
A34: TERMINAL VALUE ASSUMPTIONS
A36: Terminal Year (2029E) UFCF ($M) | B36: =F16 | G36: Linked from UFCF row above
A37: Terminal Growth Rate (g) | B37: 0.025 | G37: Long-term nuclear + clean energy demand growth
A38: Terminal Value (Gordon Growth Model) | B38: =F16/(B31-B36) | G38: TV = UFCF₂₀₂₉ / (WACC - g)
A39: Terminal Year EBITDA ($M) | B39: 10500 | G39: Base case 2029E Adj. EBITDA
A40: EV/EBITDA Exit Multiple | B40: 14 | G40: Peer group median; 12-16x range
A41: Terminal Value (EV/EBITDA Method) | B41: =B40*B41 | G41: TV = EBITDA × Exit Multiple
A44: SUMMARY: KEY METRICS FOR TASK 3 VALUATION
A46: WACC (Base) | B46: =B31 | G46: Cost of capital for DCF discounting
A47: Terminal Growth Rate | B47: =B36 | G47: Long-run FCF growth
A48: 2029E Revenue ($M) | B48: ='Income Statement'!F7 | G48: Base case projection
A49: 2029E Adj. EBITDA ($M) | B49: ='Income Statement'!F52 | G49: Non-GAAP adjusted
A50: 2029E UFCF ($M) | B50: =F16 | G50: Unlevered free cash flow
A51: Net Debt (2025A, $M) | B51: ='Balance Sheet'!F60 | G51: Pre-Calpine close
A52: Diluted Shares Outstanding (M) | B52: ='Income Statement'!F42 | G52: Base case 2026E
